<mujocoinclude>
    <!-- <light name="top" pos="0 0 2" mode="trackcom"/> -->
    <body name="torso" pos="0 0 1.4">
        <camera name="track" mode="trackcom" pos="0 -4 0" xyaxes="1 0 0 0 0 1"/>
        <joint armature="0" damping="0" limited="false" name="root" pos="0 0 0" stiffness="0" type="free"/>
        <geom fromto="0 -.07 0 0 .07 0" name="torso1" size="0.07" type="capsule"/>
        <geom name="head" pos="0 0 .19" size=".09" type="sphere" user="258"/>
        <geom fromto="-.01 -.06 -.12 -.01 .06 -.12" name="uwaist" size="0.06" type="capsule"/>
        <site name="imu"/>
        <body name="lwaist" pos="-.01 0 -0.260" quat="1.000 0 -0.002 0">
            <geom fromto="0 -.06 0 0 .06 0" name="lwaist" size="0.06" type="capsule"/>
            <joint armature="0.02" axis="0 0 1" damping="5" name="robot:abdomen_z" pos="0 0 0.065" range="-45 45" stiffness="20" type="hinge"/>
            <joint armature="0.02" axis="0 1 0" damping="5" name="robot:abdomen_y" pos="0 0 0.065" range="-75 30" stiffness="10" type="hinge"/>
            <body name="pelvis" pos="0 0 -0.165" quat="1.000 0 -0.002 0">
                <joint armature="0.02" axis="1 0 0" damping="5" name="robot:abdomen_x" pos="0 0 0.1" range="-35 35" stiffness="10" type="hinge"/>
                <geom fromto="-.02 -.07 0 -.02 .07 0" name="butt" size="0.09" type="capsule"/>
                <body name="right_thigh" pos="0 -0.1 -0.04">
                    <joint armature="0.01" axis="1 0 0" damping="5" name="robot:right_hip_x" pos="0 0 0" range="-25 5" stiffness="10" type="hinge"/>
                    <joint armature="0.01" axis="0 0 1" damping="5" name="robot:right_hip_z" pos="0 0 0" range="-60 35" stiffness="10" type="hinge"/>
                    <joint armature="0.0080" axis="0 1 0" damping="5" name="robot:right_hip_y" pos="0 0 0" range="-110 20" stiffness="20" type="hinge"/>
                    <geom fromto="0 0 0 0 0.01 -.34" name="right_thigh1" size="0.06" type="capsule"/>
                    <body name="right_shin" pos="0 0.01 -0.403">
                        <joint armature="0.0060" axis="0 -1 0" name="robot:right_knee" pos="0 0 .02" range="-160 -2" type="hinge"/>
                        <geom fromto="0 0 0 0 0 -.3" name="right_shin1" size="0.049" type="capsule"/>
                        <body name="right_foot" pos="0 0 -0.45">
                            <site name="right_foot"/>
                            <geom name="right_foot" pos="0 0 0.1" size="0.075" type="sphere" user="0"/>
                            <geom name="right_foot_1" type="sphere" pos="0.0815 0.03 -0.01" contype="2" conaffinity="1" size=".01"/>
                            <geom name="right_foot_2" type="sphere" pos="0.0815 -0.03 -0.01" contype="2" conaffinity="1" size=".01"/>
                            <geom name="right_foot_3" type="sphere" pos="-0.0815 0.03 -0.01" contype="2" conaffinity="1" size=".01"/>
                            <geom name="right_foot_4" type="sphere" pos="-0.0815 -0.03 -0.01" contype="2" conaffinity="1" size=".01"/>
                        </body>
                    </body>
                </body>
                <body name="left_thigh" pos="0 0.1 -0.04">
                    <joint armature="0.01" axis="-1 0 0" damping="5" name="robot:left_hip_x" pos="0 0 0" range="-25 5" stiffness="10" type="hinge"/>
                    <joint armature="0.01" axis="0 0 -1" damping="5" name="robot:left_hip_z" pos="0 0 0" range="-60 35" stiffness="10" type="hinge"/>
                    <joint armature="0.01" axis="0 1 0" damping="5" name="robot:left_hip_y" pos="0 0 0" range="-110 20" stiffness="20" type="hinge"/>
                    <geom fromto="0 0 0 0 -0.01 -.34" name="left_thigh1" size="0.06" type="capsule"/>
                    <body name="left_shin" pos="0 -0.01 -0.403">
                        <joint armature="0.0060" axis="0 -1 0" name="robot:left_knee" pos="0 0 .02" range="-160 -2" stiffness="1" type="hinge"/>
                        <geom fromto="0 0 0 0 0 -.3" name="left_shin1" size="0.049" type="capsule"/>
                        <body name="left_foot" pos="0 0 -0.45">
                            <site name="left_foot"/>
                            <geom name="left_foot" type="sphere" size="0.075" pos="0 0 0.1" user="0" />
                            <geom name="left_foot_1" type="sphere" pos="0.0815 0.03 -0.01" contype="2" conaffinity="1" size=".01"/>
                            <geom name="left_foot_2" type="sphere" pos="0.0815 -0.03 -0.01" contype="2" conaffinity="1" size=".01"/>
                            <geom name="left_foot_3" type="sphere" pos="-0.0815 0.03 -0.01" contype="2" conaffinity="1" size=".01"/>
                            <geom name="left_foot_4" type="sphere" pos="-0.0815 -0.03 -0.01" contype="2" conaffinity="1" size=".01"/>

                        </body>
                    </body>
                </body>
            </body>
        </body>
        <body name="right_upper_arm" pos="0 -0.17 0.06">
            <joint armature="0.0068" axis="2 1 1" name="robot:right_shoulder1" pos="0 0 0" range="-85 60" stiffness="1" type="hinge"/>
            <joint armature="0.0051" axis="0 -1 1" name="robot:right_shoulder2" pos="0 0 0" range="-85 60" stiffness="1" type="hinge"/>
            <geom fromto="0 0 0 .16 -.16 -.16" name="right_uarm1" size="0.04 0.16" type="capsule"/>
            <body name="right_lower_arm" pos=".18 -.18 -.18">
                <joint armature="0.0028" axis="0 -1 1" name="robot:right_elbow" pos="0 0 0" range="-90 50" stiffness="0" type="hinge"/>
                <geom fromto="0.01 0.01 0.01 .17 .17 .17" name="right_larm" size="0.031" type="capsule"/>
                <geom name="right_hand" pos=".18 .18 .18" size="0.04" type="sphere"/>
                <camera pos="0 0 0"/>
            </body>
        </body>
        <body name="left_upper_arm" pos="0 0.17 0.06">
            <joint armature="0.0068" axis="2 -1 1" name="robot:left_shoulder1" pos="0 0 0" range="-60 85" stiffness="1" type="hinge"/>
            <joint armature="0.0051" axis="0 1 1" name="robot:left_shoulder2" pos="0 0 0" range="-60 85" stiffness="1" type="hinge"/>
            <geom fromto="0 0 0 .16 .16 -.16" name="left_uarm1" size="0.04 0.16" type="capsule"/>
            <body name="left_lower_arm" pos=".18 .18 -.18">
                <joint armature="0.0028" axis="0 -1 -1" name="robot:left_elbow" pos="0 0 0" range="-90 50" stiffness="0" type="hinge"/>
                <geom fromto="0.01 -0.01 0.01 .17 -.17 .17" name="left_larm" size="0.031" type="capsule"/>
                <geom name="left_hand" pos=".18 -.18 .18" size="0.04" type="sphere"/>
            </body>
        </body>
    </body>
</mujocoinclude>
